Workbook

Sheet Résumé
A1: Audit des 300 principaux copyrights Gelbooru
A3: Audit effectué le 14 août 2026. Les alias ne sont proposés que lorsqu’un copyright unique est commun à tous les posts JSON échantillonnés. Les cas ambigus restent manuels.
A5: État | B5: Nombre | D5: Action | E5: Nombre
A6: Wiki présent | B6: =COUNTIF('Rangs 1-200'!$D$2:$D$201,A6)+COUNTIF('Rangs 201-300'!$D$2:$D$101,A6) -> 231 | D6: À créer | E6: =COUNTIF('Rangs 1-200'!$I$2:$I$201,D6)+COUNTIF('Rangs 201-300'!$I$2:$I$101,D6) -> 46
A7: Alias → wiki canonique | B7: =COUNTIF('Rangs 1-200'!$D$2:$D$201,A7)+COUNTIF('Rangs 201-300'!$D$2:$D$101,A7) -> 14 | D7: Brouillon prêt à publier | E7: =COUNTIF('Rangs 1-200'!$I$2:$I$201,D7)+COUNTIF('Rangs 201-300'!$I$2:$I$101,D7) -> 0
A8: Wiki absent | B8: =COUNTIF('Rangs 1-200'!$D$2:$D$201,A8)+COUNTIF('Rangs 201-300'!$D$2:$D$101,A8) -> 46 | D8: Vérifier mise à jour (>5 ans) | E8: =COUNTIF('Rangs 1-200'!$I$2:$I$201,D8)+COUNTIF('Rangs 201-300'!$I$2:$I$101,D8) -> 45
A9: Alias ambigu | B9: =COUNTIF('Rangs 1-200'!$D$2:$D$201,A9)+COUNTIF('Rangs 201-300'!$D$2:$D$101,A9) -> 7 | D9: Jauger manuellement | E9: =COUNTIF('Rangs 1-200'!$I$2:$I$201,D9)+COUNTIF('Rangs 201-300'!$I$2:$I$101,D9) -> 68
A10: Échantillon insuffisant | B10: =COUNTIF('Rangs 1-200'!$D$2:$D$201,A10)+COUNTIF('Rangs 201-300'!$D$2:$D$101,A10) -> 1 | D10: Contrôle manuel requis | E10: =COUNTIF('Rangs 1-200'!$I$2:$I$201,D10)+COUNTIF('Rangs 201-300'!$I$2:$I$101,D10) -> 9
A11: Wiki absent / aucun alias commun | B11: =COUNTIF('Rangs 1-200'!$D$2:$D$201,A11)+COUNTIF('Rangs 201-300'!$D$2:$D$101,A11) -> 1 | D11: Aucun besoin évident | E11: =COUNTIF('Rangs 1-200'!$I$2:$I$201,D11)+COUNTIF('Rangs 201-300'!$I$2:$I$101,D11) -> 116
A14: Utilisation : filtre la colonne Action conseillée, puis clique sur ↗ dans Lien wiki. Pour un alias, le lien mène directement au wiki du tag canonique ; l’URL complète reste disponible en secours.

Sheet Rangs 1-200
A1: Rang | B1: Tag copyright | C1: Images | D1: État du wiki | E1: Alias canonique | F1: Lien wiki (↗) | G1: Dernière mise à jour | H1: Travail local | I1: Action conseillée | J1: Candidats / remarque | K1: URL du wiki (secours)
A2: 1 | B2: original | C2: 1687758 | D2: Wiki présent | F2: =HYPERLINK(K2,"↗") -> ↗ | G2: 45328.311 | H2: Non traité | I2: Aucun besoin évident | K2: https://gelbooru.com/index.php?page=wiki&s=view&id=129
A3: 2 | B3: touhou | C3: 1009014 | D3: Wiki présent | F3: =HYPERLINK(K3,"↗") -> ↗ | H3: Non traité | I3: Jauger manuellement | K3: https://gelbooru.com/index.php?page=wiki&s=view&id=33
A4: 3 | B4: nintendo | C4: 895770 | D4: Wiki présent | F4: =HYPERLINK(K4,"↗") -> ↗ | H4: Non traité | I4: Jauger manuellement | K4: https://gelbooru.com/index.php?page=wiki&s=view&id=6035
A5: 4 | B5: pokemon | C5: 533357 | D5: Wiki présent | F5: =HYPERLINK(K5,"↗") -> ↗ | H5: Non traité | I5: Jauger manuellement | K5: https://gelbooru.com/index.php?page=wiki&s=view&id=6888
A6: 5 | B6: kantai_collection | C6: 515188 | D6: Wiki présent | F6: =HYPERLINK(K6,"↗") -> ↗ | G6: 42100.807 | H6: Non traité | I6: Vérifier mise à jour (>5 ans) | K6: https://gelbooru.com/index.php?page=wiki&s=view&id=11215
A7: 6 | B7: blue_archive | C7: 440806 | D7: Wiki présent | F7: =HYPERLINK(K7,"↗") -> ↗ | G7: 46242.905 | H7: Non traité | I7: Aucun besoin évident | K7: https://gelbooru.com/index.php?page=wiki&s=view&id=27326
A8: 7 | B8: fate_(series) | C8: 424708 | D8: Wiki présent | F8: =HYPERLINK(K8,"↗") -> ↗ | G8: 46247.947 | H8: Brouillon prêt | I8: Aucun besoin évident | K8: https://gelbooru.com/index.php?page=wiki&s=view&id=27238
A9: 8 | B9: hololive | C9: 325946 | D9: Wiki présent | F9: =HYPERLINK(K9,"↗") -> ↗ | H9: Non traité | I9: Jauger manuellement | K9: https://gelbooru.com/index.php?page=wiki&s=view&id=26117
A10: 9 | B10: genshin_impact | C10: 318339 | D10: Wiki présent | F10: =HYPERLINK(K10,"↗") -> ↗ | G10: 46247.404 | H10: Brouillon prêt | I10: Aucun besoin évident | K10: https://gelbooru.com/index.php?page=wiki&s=view&id=26717
A11: 10 | B11: fate/grand_order | C11: 308099 | D11: Wiki présent | F11: =HYPERLINK(K11,"↗") -> ↗ | G11: 45021.401 | H11: Non traité | I11: Aucun besoin évident | K11: https://gelbooru.com/index.php?page=wiki&s=view&id=25685
A12: 11 | B12: idolmaster | C12: 303464 | D12: Wiki présent | F12: =HYPERLINK(K12,"↗") -> ↗ | H12: Brouillon prêt | I12: Jauger manuellement | K12: https://gelbooru.com/index.php?page=wiki&s=view&id=436
A13: 12 | B13: arknights | C13: 220474 | D13: Wiki présent | F13: =HYPERLINK(K13,"↗") -> ↗ | H13: Non traité | I13: Jauger manuellement | K13: https://gelbooru.com/index.php?page=wiki&s=view&id=26560
A14: 13 | B14: vocaloid | C14: 216903 | D14: Wiki présent | F14: =HYPERLINK(K14,"↗") -> ↗ | G14: 42700.183 | H14: Non traité | I14: Vérifier mise à jour (>5 ans) | K14: https://gelbooru.com/index.php?page=wiki&s=view&id=2179
A15: 14 | B15: umamusume | C15: 203874 | D15: Wiki présent | F15: =HYPERLINK(K15,"↗") -> ↗ | H15: Non traité | I15: Jauger manuellement | K15: https://gelbooru.com/index.php?page=wiki&s=view&id=22977
A16: 15 | B16: love_live! | C16: 190930 | D16: Wiki présent | F16: =HYPERLINK(K16,"↗") -> ↗ | H16: Non traité | I16: Jauger manuellement | K16: https://gelbooru.com/index.php?page=wiki&s=view&id=28419
A17: 16 | B17: honkai_(series) | C17: 179381 | D17: Wiki présent | F17: =HYPERLINK(K17,"↗") -> ↗ | G17: 46247.39 | H17: Brouillon prêt | I17: Aucun besoin évident | K17: https://gelbooru.com/index.php?page=wiki&s=view&id=32881
A18: 17 | B18: azur_lane | C18: 162621 | D18: Wiki présent | F18: =HYPERLINK(K18,"↗") -> ↗ | G18: 45658.886 | H18: Non traité | I18: Aucun besoin évident | K18: https://gelbooru.com/index.php?page=wiki&s=view&id=23487
A19: 18 | B19: fire_emblem | C19: 155059 | D19: Wiki présent | F19: =HYPERLINK(K19,"↗") -> ↗ | H19: Non traité | I19: Jauger manuellement | K19: https://gelbooru.com/index.php?page=wiki&s=view&id=22598
A20: 19 | B20: idolmaster_cinderella_girls | C20: 146653 | D20: Wiki présent | F20: =HYPERLINK(K20,"↗") -> ↗ | H20: Brouillon prêt | I20: Jauger manuellement | K20: https://gelbooru.com/index.php?page=wiki&s=view&id=12488
A21: 20 | B21: digimon | C21: 137090 | D21: Wiki présent | F21: =HYPERLINK(K21,"↗") -> ↗ | H21: Non traité | I21: Jauger manuellement | K21: https://gelbooru.com/index.php?page=wiki&s=view&id=11536
A22: 21 | B22: final_fantasy | C22: 131320 | D22: Wiki présent | F22: =HYPERLINK(K22,"↗") -> ↗ | H22: Non traité | I22: Jauger manuellement | K22: https://gelbooru.com/index.php?page=wiki&s=view&id=2341
A23: 22 | B23: honkai:_star_rail | C23: 126118 | D23: Wiki présent | F23: =HYPERLINK(K23,"↗") -> ↗ | G23: 46247.401 | H23: Brouillon prêt | I23: Aucun besoin évident | K23: https://gelbooru.com/index.php?page=wiki&s=view&id=32896
A24: 23 | B24: hololive_english | C24: 112584 | D24: Wiki présent | F24: =HYPERLINK(K24,"↗") -> ↗ | G24: 45542.257 | H24: Non traité | I24: Aucun besoin évident | K24: https://gelbooru.com/index.php?page=wiki&s=view&id=26725
A25: 24 | B25: one_piece | C25: 110327 | D25: Wiki présent | F25: =HYPERLINK(K25,"↗") -> ↗ | H25: Non traité | I25: Jauger manuellement | K25: https://gelbooru.com/index.php?page=wiki&s=view&id=229
A26: 25 | B26: zenless_zone_zero | C26: 105532 | D26: Wiki présent | F26: =HYPERLINK(K26,"↗") -> ↗ | G26: 46245.274 | H26: Non traité | I26: Aucun besoin évident | K26: https://gelbooru.com/index.php?page=wiki&s=view&id=31590
A27: 26 | B27: nijisanji | C27: 92264 | D27: Wiki présent | F27: =HYPERLINK(K27,"↗") -> ↗ | G27: 44773.108 | H27: Non traité | I27: Aucun besoin évident | K27: https://gelbooru.com/index.php?page=wiki&s=view&id=26776
A28: 27 | B28: indie_virtual_youtuber | C28: 88852 | D28: Wiki présent | F28: =HYPERLINK(K28,"↗") -> ↗ | G28: 45793.889 | H28: Non traité | I28: Aucun besoin évident | K28: https://gelbooru.com/index.php?page=wiki&s=view&id=30651
A29: 28 | B29: gundam | C29: 84694 | D29: Wiki présent | F29: =HYPERLINK(K29,"↗") -> ↗ | H29: Non traité | I29: Jauger manuellement | K29: https://gelbooru.com/index.php?page=wiki&s=view&id=12503
A30: 29 | B30: girls'_frontline | C30: 81059 | D30: Wiki présent | F30: =HYPERLINK(K30,"↗") -> ↗ | H30: Non traité | I30: Jauger manuellement | K30: https://gelbooru.com/index.php?page=wiki&s=view&id=32678
A31: 30 | B31: girls_und_panzer | C31: 80341 | D31: Wiki présent | F31: =HYPERLINK(K31,"↗") -> ↗ | G31: 44271.42 | H31: Non traité | I31: Vérifier mise à jour (>5 ans) | K31: https://gelbooru.com/index.php?page=wiki&s=view&id=21928
A32: 31 | B32: mahou_shoujo_madoka_magica | C32: 79832 | D32: Wiki présent | F32: =HYPERLINK(K32,"↗") -> ↗ | H32: Non traité | I32: Jauger manuellement | K32: https://gelbooru.com/index.php?page=wiki&s=view&id=2689
A33: 32 | B33: gfl | C33: 77205 | D33: Wiki absent / aucun alias commun | H33: Non traité | I33: Contrôle manuel requis
A34: 33 | B34: precure | C34: 76121 | D34: Wiki présent | F34: =HYPERLINK(K34,"↗") -> ↗ | H34: Non traité | I34: Jauger manuellement | K34: https://gelbooru.com/index.php?page=wiki&s=view&id=11458
A35: 34 | B35: danganronpa_(series) | C35: 71911 | D35: Wiki présent | F35: =HYPERLINK(K35,"↗") -> ↗ | G35: 46247.418 | H35: Brouillon prêt | I35: Aucun besoin évident | K35: https://gelbooru.com/index.php?page=wiki&s=view&id=32904
A36: 35 | B36: capcom | C36: 70968 | D36: Wiki présent | F36: =HYPERLINK(K36,"↗") -> ↗ | H36: Non traité | I36: Jauger manuellement | K36: https://gelbooru.com/index.php?page=wiki&s=view&id=1415
A37: 36 | B37: boku_no_hero_academia | C37: 70225 | D37: Wiki présent | F37: =HYPERLINK(K37,"↗") -> ↗ | H37: Non traité | I37: Jauger manuellement | K37: https://gelbooru.com/index.php?page=wiki&s=view&id=23484
A38: 37 | B38: naruto_(series) | C38: 69478 | D38: Wiki présent | F38: =HYPERLINK(K38,"↗") -> ↗ | G38: 46241.253 | H38: Non traité | I38: Aucun besoin évident | K38: https://gelbooru.com/index.php?page=wiki&s=view&id=26778
A39: 38 | B39: puella_magi_madoka_magica | C39: 63104 | D39: Wiki présent | F39: =HYPERLINK(K39,"↗") -> ↗ | G39: 41707.641 | H39: Non traité | I39: Vérifier mise à jour (>5 ans) | K39: https://gelbooru.com/index.php?page=wiki&s=view&id=14145
A40: 39 | B40: kemono_friends | C40: 61640 | D40: Wiki présent | F40: =HYPERLINK(K40,"↗") -> ↗ | H40: Non traité | I40: Jauger manuellement | K40: https://gelbooru.com/index.php?page=wiki&s=view&id=21317
...

Sheet Rangs 201-300
A1: Rang | B1: Tag copyright | C1: Images | D1: État du wiki | E1: Alias canonique | F1: Lien wiki (↗) | G1: Dernière mise à jour | H1: Travail local | I1: Action conseillée | J1: Candidats / remarque | K1: URL du wiki (secours)
A2: 201 | B2: botw | C2: 14444 | D2: Wiki présent | H2: Non traité | I2: Contrôle manuel requis | J2: nintendo, the_legend_of_zelda, the_legend_of_zelda:_breath_of_the_wild | K2: https://gelbooru.com/index.php?page=wiki&s=&s=view&id=19919
A3: 202 | B3: taimanin_rpgx | C3: 14439 | D3: Wiki absent | H3: Non traité | I3: À créer
A4: 203 | B4: dragon_ball_super | C4: 14378 | D4: Wiki présent | F4: =HYPERLINK(K4,"↗") -> ↗ | H4: Brouillon prêt | I4: Jauger manuellement | K4: https://gelbooru.com/index.php?page=wiki&s=view&id=22079
A5: 204 | B5: queen's_blade | C5: 14228 | D5: Wiki présent | F5: =HYPERLINK(K5,"↗") -> ↗ | H5: Non traité | I5: Jauger manuellement | K5: https://gelbooru.com/index.php?page=wiki&s=view&id=9533
A6: 205 | B6: zzz_(game) | C6: 14227 | D6: Alias → wiki canonique | E6: zenless_zone_zero | F6: =HYPERLINK(K6,"↗") -> ↗ | G6: 46245.274 | H6: Non traité | I6: Alias résolu — contrôler le wiki | J6: zenless_zone_zero | K6: https://gelbooru.com/index.php?page=wiki&s=view&id=31590
A7: 206 | B7: idolmaster_million_live!_theater_days | C7: 14117 | D7: Wiki présent | F7: =HYPERLINK(K7,"↗") -> ↗ | G7: 46247.462 | H7: Brouillon prêt | I7: Aucun besoin évident | K7: https://gelbooru.com/index.php?page=wiki&s=view&id=32933
A8: 207 | B8: cardcaptor_sakura | C8: 14077 | D8: Wiki présent | F8: =HYPERLINK(K8,"↗") -> ↗ | H8: Non traité | I8: mise à jour | J8: mettre à jour, faire les fiches personnages. | K8: https://gelbooru.com/index.php?page=wiki&s=view&id=20937
A9: 208 | B9: dungeon_meshi | C9: 14072 | D9: Wiki présent | F9: =HYPERLINK(K9,"↗") -> ↗ | G9: 46194.858 | H9: Non traité | I9: Aucun besoin évident | K9: https://gelbooru.com/index.php?page=wiki&s=view&id=31907
A10: 209 | B10: eiyuu_densetsu | C10: 13937 | D10: Wiki absent | H10: Non traité | I10: À créer
A11: 210 | B11: garou_(game_series) | C11: 13936 | D11: Alias → wiki canonique | E11: fatal_fury | F11: =HYPERLINK(K11,"↗") -> ↗ | G11: 41559.342 | H11: Non traité | I11: mise à jour | J11: fatal_fury | K11: https://gelbooru.com/index.php?page=wiki&s=view&id=12224
A12: 211 | B12: one-punch_man | C12: 13874 | D12: Wiki présent | F12: =HYPERLINK(K12,"↗") -> ↗ | G12: 44805.799 | H12: Non traité | I12: Aucun besoin évident | K12: https://gelbooru.com/index.php?page=wiki&s=view&id=19056
A13: 212 | B13: rebuild_of_evangelion | C13: 13846 | D13: Wiki présent | F13: =HYPERLINK(K13,"↗") -> ↗ | G13: 44264.47 | H13: Non traité | I13: Aucun besoin évident | K13: https://gelbooru.com/index.php?page=wiki&s=view&id=9172
A14: 213 | B14: super_mario_bros._1 | C14: 13813 | D14: Alias → wiki canonique | E14: super_mario_bros | H14: Non traité | I14: Aucun besoin évident | K14: https://gelbooru.com/index.php?page=wiki&s=view&id=56
A15: 214 | B15: to_love-ru | C15: 13752 | D15: Wiki présent | F15: =HYPERLINK(K15,"↗") -> ↗ | H15: Non traité | I15: mise à jour | K15: https://gelbooru.com/index.php?page=wiki&s=view&id=24533
A16: 215 | B16: samurai_spirits | C16: 13632 | D16: Wiki présent | F16: =HYPERLINK(K16,"↗") -> ↗ | G16: 42183.69 | H16: Non traité | I16: mise à jour | K16: https://gelbooru.com/index.php?page=wiki&s=view&id=17035
A17: 216 | B17: tengen_toppa_gurren_lagann | C17: 13581 | D17: Wiki présent | F17: =HYPERLINK(K17,"↗") -> ↗ | H17: Non traité | I17: mise à jour | K17: https://gelbooru.com/index.php?page=wiki&s=view&id=30
A18: 217 | B18: elden_ring | C18: 13393 | D18: Wiki présent | F18: =HYPERLINK(K18,"↗") -> ↗ | G18: 46247.417 | H18: Non traité | I18: Aucun besoin évident | K18: https://gelbooru.com/index.php?page=wiki&s=view&id=32903
A19: 218 | B19: vspo! | C19: 13326 | D19: Wiki présent | F19: =HYPERLINK(K19,"↗") -> ↗ | G19: 45807.391 | H19: Non traité | I19: Aucun besoin évident | K19: https://gelbooru.com/index.php?page=wiki&s=view&id=30668
A20: 219 | B20: saibou_shinkyoku | C20: 13271 | D20: Wiki absent | H20: Non traité | I20: À créer
A21: 220 | B21: fire_emblem_engage | C21: 13225 | D21: Wiki absent | H21: Non traité | I21: À créer
A22: 221 | B22: kamen_rider | C22: 13189 | D22: Wiki présent | F22: =HYPERLINK(K22,"↗") -> ↗ | H22: Non traité | I22: Aucun besoin évident | K22: https://gelbooru.com/index.php?page=wiki&s=view&id=14356
A23: 222 | B23: magia_record:_mahou_shoujo_madoka_magica_gaiden | C23: 13092 | D23: Wiki absent | H23: Non traité | I23: À créer | J23: le central existe, mais verrouillé https://gelbooru.com/index.php?page=wiki&s=view&id=2689
A24: 223 | B24: senki_zesshou_symphogear | C24: 12967 | D24: Wiki absent | H24: Non traité | I24: À créer
A25: 224 | B25: umineko_no_naku_koro_ni | C25: 12955 | D25: Wiki absent | H25: Non traité | I25: À créer
A26: 225 | B26: love_live!_hasunosora_jogakuin_school_idol_club | C26: 12914 | D26: Alias ambigu | H26: Non traité | I26: Aucun besoin évident | J26: love_live!, love_live!_hasu_no_sora_jogakuin_school_idol_club
A27: 226 | B27: alien_stage | C27: 12889 | D27: Wiki absent | H27: Non traité | I27: À créer
A28: 227 | B28: ensemble_stars! | C28: 12770 | D28: Wiki présent | F28: =HYPERLINK(K28,"↗") -> ↗ | G28: 44607.922 | H28: Non traité | I28: Aucun besoin évident | K28: https://gelbooru.com/index.php?page=wiki&s=view&id=27979
A29: 228 | B29: mahou_shoujo_lyrical_nanoha_strikers | C29: 12726 | D29: Wiki présent | F29: =HYPERLINK(K29,"↗") -> ↗ | H29: Déjà publié (uploaded) | I29: Aucun besoin évident | K29: https://gelbooru.com/index.php?page=wiki&s=view&id=32757
A30: 229 | B30: panty_&_stocking_with_garterbelt | C30: 12590 | D30: Wiki présent | F30: =HYPERLINK(K30,"↗") -> ↗ | G30: 45924.47 | H30: Non traité | I30: Aucun besoin évident | K30: https://gelbooru.com/index.php?page=wiki&s=view&id=722
A31: 230 | B31: boruto:_naruto_next_generations | C31: 12571 | D31: Wiki présent | F31: =HYPERLINK(K31,"↗") -> ↗ | G31: 46246.541 | H31: Non traité | I31: Aucun besoin évident | K31: https://gelbooru.com/index.php?page=wiki&s=view&id=32884
A32: 231 | B32: pokemon_heartgold_and_soulsilver | C32: 12533 | D32: Wiki absent | H32: Non traité | I32: À créer
A33: 232 | B33: atelier_(series) | C33: 12454 | D33: Wiki absent | H33: Non traité | I33: À créer
A34: 233 | B34: overwatch_1 | C34: 12359 | D34: Alias → wiki canonique | E34: overwatch | H34: Non traité | I34: Aucun besoin évident | J34: overwatch | K34: https://gelbooru.com/index.php?page=wiki&s=&s=view&id=32970
A35: 234 | B35: gundam_suisei_no_majo | C35: 12159 | D35: Wiki présent | F35: =HYPERLINK(K35,"↗") -> ↗ | G35: 45233.225 | H35: Non traité | I35: Aucun besoin évident | K35: https://gelbooru.com/index.php?page=wiki&s=view&id=28939
A36: 235 | B36: tekken | C36: 12140 | D36: Wiki présent | F36: =HYPERLINK(K36,"↗") -> ↗ | H36: Non traité | I36: Jauger manuellement | K36: https://gelbooru.com/index.php?page=wiki&s=view&id=4049
A37: 236 | B37: boruto_(series) | C37: 12118 | D37: Wiki présent | F37: =HYPERLINK(K37,"↗") -> ↗ | G37: 46241.263 | H37: Non traité | I37: Aucun besoin évident | K37: https://gelbooru.com/index.php?page=wiki&s=view&id=32637
A38: 237 | B38: last_origin | C38: 11930 | D38: Wiki présent | F38: =HYPERLINK(K38,"↗") -> ↗ | G38: 44305.803 | H38: Non traité | I38: Vérifier mise à jour (>5 ans) | K38: https://gelbooru.com/index.php?page=wiki&s=view&id=27150
A39: 238 | B39: bang_dream!_ave_mujica | C39: 11877 | D39: Alias → wiki canonique | E39: bang_dream! | F39: =HYPERLINK(K39,"↗") -> ↗ | G39: 45311.636 | H39: Non traité | I39: Alias résolu — contrôler le wiki | J39: bang_dream! | K39: https://gelbooru.com/index.php?page=wiki&s=view&id=24895
A40: 239 | B40: rozen_maiden | C40: 11860 | D40: Wiki absent | H40: Non traité | I40: À créer
...

Sheet À traiter
A1: Rang | B1: Tag copyright | C1: Images | D1: État du wiki | E1: Alias canonique | F1: Lien wiki (↗) | G1: Dernière mise à jour | H1: Travail local | I1: Action conseillée | J1: Candidats / remarque | K1: URL du wiki (secours)
A2: 53 | B2: mahou_shoujo_madoka_magica_(anime) | C2: 51944 | D2: Wiki absent | H2: Non traité | I2: À créer
A3: 72 | B3: fire_emblem:_three_houses | C3: 39206 | D3: Wiki absent | H3: Non traité | I3: À créer
A4: 75 | B4: final_fantasy_xiv | C4: 36040 | D4: Wiki absent | H4: Non traité | I4: À créer
A5: 93 | B5: love_live!_hasu_no_sora_jogakuin_school_idol_club | C5: 30768 | D5: Wiki absent | H5: Non traité | I5: À créer
A6: 100 | B6: fire_emblem_fates | C6: 28967 | D6: Wiki absent | H6: Non traité | I6: À créer
A7: 114 | B7: xenoblade_chronicles_2 | C7: 25954 | D7: Wiki absent | H7: Non traité | I7: À créer
A8: 116 | B8: utau | C8: 25281 | D8: Wiki absent | H8: Non traité | I8: À créer
A9: 142 | B9: pokemon_x_and_y | C9: 21074 | D9: Wiki absent | H9: Non traité | I9: À créer
A10: 167 | B10: pokemon_black_2_and_white_2 | C10: 17359 | D10: Wiki absent | H10: Non traité | I10: À créer
A11: 170 | B11: nijisanji_en | C11: 16838 | D11: Wiki absent | H11: Non traité | I11: À créer
A12: 173 | B12: bang_dream!_girls_band_party! | C12: 16686 | D12: Wiki absent | H12: Non traité | I12: À créer
A13: 178 | B13: tsukihime | C13: 16417 | D13: Wiki absent | H13: Non traité | I13: À créer
... A50: 32 | B50: gfl | C50: 77205 | D50: Wiki absent / aucun alias commun | H50: Non traité | I50: Contrôle manuel requis
A51: 62 | B51: puella_magi_madoka_magica_(anime) | C51: 45474 | D51: Alias ambigu | H51: Non traité | I51: Contrôle manuel requis | J51: mahou_shoujo_madoka_magica, mahou_shoujo_madoka_magica_(anime)
A52: 105 | B52: link!_like!_love_live! | C52: 28196 | D52: Alias ambigu | H52: Non traité | I52: Contrôle manuel requis | J52: love_live!, love_live!_hasu_no_sora_jogakuin_school_idol_club
A53: 113 | B53: ffvii | C53: 26035 | D53: Alias ambigu | H53: Non traité | I53: Contrôle manuel requis | J53: final_fantasy, final_fantasy_vii
A54: 164 | B54: ffxiv | C54: 17740 | D54: Alias ambigu | H54: Non traité | I54: Contrôle manuel requis | J54: final_fantasy, final_fantasy_xiv
A55: 171 | B55: dbz | C55: 16818 | D55: Échantillon insuffisant | H55: Non traité | I55: Contrôle manuel requis
A56: 201 | B56: botw | C56: 14444 | D56: Alias ambigu | H56: Non traité | I56: Contrôle manuel requis | J56: nintendo, the_legend_of_zelda, the_legend_of_zelda:_breath_of_the_wild
A57: 225 | B57: love_live!_hasunosora_jogakuin_school_idol_club | C57: 12914 | D57: Alias ambigu | H57: Non traité | I57: Contrôle manuel requis | J57: love_live!, love_live!_hasu_no_sora_jogakuin_school_idol_club
A58: 267 | B58: breath_of_the_wild | C58: 10231 | D58: Alias ambigu | H58: Non traité | I58: Contrôle manuel requis | J58: nintendo, the_legend_of_zelda, the_legend_of_zelda:_breath_of_the_wild
A59: 284 | B59: totk | C59: 9554 | D59: Alias ambigu | H59: Non traité | I59: Contrôle manuel requis | J59: nintendo, the_legend_of_zelda, the_legend_of_zelda:_tears_of_the_kingdom
A60: 2 | B60: touhou | C60: 1009014 | D60: Wiki présent | F60: =HYPERLINK(K60,"↗") -> ↗ | H60: Non traité | I60: Jauger manuellement | K60: https://gelbooru.com/index.php?page=wiki&s=view&id=33
A61: 3 | B61: nintendo | C61: 895770 | D61: Wiki présent | F61: =HYPERLINK(K61,"↗") -> ↗ | H61: Non traité | I61: Jauger manuellement | K61: https://gelbooru.com/index.php?page=wiki&s=view&id=6035
A62: 4 | B62: pokemon | C62: 533357 | D62: Wiki présent | F62: =HYPERLINK(K62,"↗") -> ↗ | H62: Non traité | I62: Jauger manuellement | K62: https://gelbooru.com/index.php?page=wiki&s=view&id=6888
A63: 5 | B63: kantai_collection | C63: 515188 | D63: Wiki présent | F63: =HYPERLINK(K63,"↗") -> ↗ | G63: 42100.807 | H63: Non traité | I63: Vérifier mise à jour (>5 ans) | K63: https://gelbooru.com/index.php?page=wiki&s=view&id=11215
A64: 8 | B64: hololive | C64: 325946 | D64: Wiki présent | F64: =HYPERLINK(K64,"↗") -> ↗ | H64: Non traité | I64: Jauger manuellement | K64: https://gelbooru.com/index.php?page=wiki&s=view&id=26117
A65: 11 | B65: idolmaster | C65: 303464 | D65: Wiki présent | F65: =HYPERLINK(K65,"↗") -> ↗ | H65: Brouillon prêt | I65: Jauger manuellement | K65: https://gelbooru.com/index.php?page=wiki&s=view&id=436
A66: 12 | B66: arknights | C66: 220474 | D66: Wiki présent | F66: =HYPERLINK(K66,"↗") -> ↗ | H66: Non traité | I66: Jauger manuellement | K66: https://gelbooru.com/index.php?page=wiki&s=view&id=26560
A67: 13 | B67: vocaloid | C67: 216903 | D67: Wiki présent | F67: =HYPERLINK(K67,"↗") -> ↗ | G67: 42700.183 | H67: Non traité | I67: Vérifier mise à jour (>5 ans) | K67: https://gelbooru.com/index.php?page=wiki&s=view&id=2179
A68: 14 | B68: umamusume | C68: 203874 | D68: Wiki présent | F68: =HYPERLINK(K68,"↗") -> ↗ | H68: Non traité | I68: Jauger manuellement | K68: https://gelbooru.com/index.php?page=wiki&s=view&id=22977
A69: 15 | B69: love_live! | C69: 190930 | D69: Wiki présent | F69: =HYPERLINK(K69,"↗") -> ↗ | H69: Non traité | I69: Jauger manuellement | K69: https://gelbooru.com/index.php?page=wiki&s=view&id=28419
A70: 18 | B70: fire_emblem | C70: 155059 | D70: Wiki présent | F70: =HYPERLINK(K70,"↗") -> ↗ | H70: Non traité | I70: Jauger manuellement | K70: https://gelbooru.com/index.php?page=wiki&s=view&id=22598
A71: 19 | B71: idolmaster_cinderella_girls | C71: 146653 | D71: Wiki présent | F71: =HYPERLINK(K71,"↗") -> ↗ | H71: Brouillon prêt | I71: Jauger manuellement | K71: https://gelbooru.com/index.php?page=wiki&s=view&id=12488
A72: 20 | B72: digimon | C72: 137090 | D72: Wiki présent | F72: =HYPERLINK(K72,"↗") -> ↗ | H72: Non traité | I72: Jauger manuellement | K72: https://gelbooru.com/index.php?page=wiki&s=view&id=11536
A73: 21 | B73: final_fantasy | C73: 131320 | D73: Wiki présent | F73: =HYPERLINK(K73,"↗") -> ↗ | H73: Non traité | I73: Jauger manuellement | K73: https://gelbooru.com/index.php?page=wiki&s=view&id=2341
A74: 24 | B74: one_piece | C74: 110327 | D74: Wiki présent | F74: =HYPERLINK(K74,"↗") -> ↗ | H74: Non traité | I74: Jauger manuellement | K74: https://gelbooru.com/index.php?page=wiki&s=view&id=229
A75: 28 | B75: gundam | C75: 84694 | D75: Wiki présent | F75: =HYPERLINK(K75,"↗") -> ↗ | H75: Non traité | I75: Jauger manuellement | K75: https://gelbooru.com/index.php?page=wiki&s=view&id=12503
A76: 29 | B76: girls'_frontline | C76: 81059 | D76: Wiki présent | F76: =HYPERLINK(K76,"↗") -> ↗ | H76: Non traité | I76: Jauger manuellement | K76: https://gelbooru.com/index.php?page=wiki&s=view&id=32678
...
